Traceback (most recent call last):
  File "/opt/hostedtoolcache/Python/3.12.10/x64/lib/python3.12/site-packages/jupyter_cache/executors/utils.py", line 58, in single_nb_execution
    executenb(
  File "/opt/hostedtoolcache/Python/3.12.10/x64/lib/python3.12/site-packages/nbclient/client.py", line 1319, in execute
    return NotebookClient(nb=nb, resources=resources, km=km, **kwargs).execute()
           ^^^^^^^^^^^^^^^^^^^^^^^^^^^^^^^^^^^^^^^^^^^^^^^^^^^^^^^^^^^^^^^^^^^^^
  File "/opt/hostedtoolcache/Python/3.12.10/x64/lib/python3.12/site-packages/jupyter_core/utils/__init__.py", line 165, in wrapped
    return loop.run_until_complete(inner)
           ^^^^^^^^^^^^^^^^^^^^^^^^^^^^^^
  File "/opt/hostedtoolcache/Python/3.12.10/x64/lib/python3.12/asyncio/base_events.py", line 691, in run_until_complete
    return future.result()
           ^^^^^^^^^^^^^^^
  File "/opt/hostedtoolcache/Python/3.12.10/x64/lib/python3.12/site-packages/nbclient/client.py", line 709, in async_execute
    await self.async_execute_cell(
  File "/opt/hostedtoolcache/Python/3.12.10/x64/lib/python3.12/site-packages/nbclient/client.py", line 1062, in async_execute_cell
    await self._check_raise_for_error(cell, cell_index, exec_reply)
  File "/opt/hostedtoolcache/Python/3.12.10/x64/lib/python3.12/site-packages/nbclient/client.py", line 918, in _check_raise_for_error
    raise CellExecutionError.from_cell_and_msg(cell, exec_reply_content)
nbclient.exceptions.CellExecutionError: An error occurred while executing the following cell:
------------------
for source in sources:
    hyps = nuda.astro.gw_hyps( source = source )
    print(f'source: {source}, hyps: {hyps}')
    for hyp in hyps:
        gw = nuda.astro.setupGW( source = source, hyp = hyp )
    gwav = nuda.astro.setupGWAverage( source = source )
------------------

----- stdout -----
source: GW170817, hyps: [1, 2, 3, 4, 5]
------------------

[31m---------------------------------------------------------------------------[39m
[31mFileNotFoundError[39m                         Traceback (most recent call last)
[36mCell[39m[36m [39m[32mIn[5][39m[32m, line 5[39m
[32m      3[39m [38;5;28mprint[39m([33mf[39m[33m'[39m[33msource: [39m[38;5;132;01m{[39;00msource[38;5;132;01m}[39;00m[33m, hyps: [39m[38;5;132;01m{[39;00mhyps[38;5;132;01m}[39;00m[33m'[39m)
[32m      4[39m [38;5;28;01mfor[39;00m hyp [38;5;129;01min[39;00m hyps:
[32m----> [39m[32m5[39m     gw = [43mnuda[49m[43m.[49m[43mastro[49m[43m.[49m[43msetupGW[49m[43m([49m[43m [49m[43msource[49m[43m [49m[43m=[49m[43m [49m[43msource[49m[43m,[49m[43m [49m[43mhyp[49m[43m [49m[43m=[49m[43m [49m[43mhyp[49m[43m [49m[43m)[49m
[32m      6[39m gwav = nuda.astro.setupGWAverage( source = source )

[36mFile [39m[32m~/work/nucleardatapy/nucleardatapy/version-0.2/nucleardatapy/astro/setup_gw.py:160[39m, in [36msetupGW.__init__[39m[34m(self, source, hyp)[39m
[32m    156[39m         [38;5;28mself[39m.marker = [33m'[39m[33ms[39m[33m'[39m
[32m    157[39m [38;5;66;03m#[39;00m
[32m    158[39m [38;5;66;03m# read file from `file_in`[39;00m
[32m    159[39m [38;5;66;03m#[39;00m
[32m--> [39m[32m160[39m [38;5;28;01mwith[39;00m [38;5;28;43mopen[39;49m[43m([49m[43mfile_in[49m[43m,[49m[33;43m'[39;49m[33;43mr[39;49m[33;43m'[39;49m[43m)[49m [38;5;28;01mas[39;00m file:
[32m    161[39m     [38;5;28;01mfor[39;00m line [38;5;129;01min[39;00m file:
[32m    162[39m         [38;5;28;01mif[39;00m [33m'[39m[33m#[39m[33m'[39m [38;5;129;01min[39;00m line: [38;5;28;01mcontinue[39;00m

[31mFileNotFoundError[39m: [Errno 2] No such file or directory: '/home/runner/work/nucleardatapy/nucleardatapy/version-0.2/nucleardatapy/data/astro/gw/GW170817.dat'

