Traceback (most recent call last):
  File "/opt/hostedtoolcache/Python/3.12.10/x64/lib/python3.12/site-packages/jupyter_core/utils/__init__.py", line 154, in wrapped
    asyncio.get_running_loop()
RuntimeError: no running event loop

During handling of the above exception, another exception occurred:

Traceback (most recent call last):
  File "/opt/hostedtoolcache/Python/3.12.10/x64/lib/python3.12/site-packages/jupyter_cache/executors/utils.py", line 58, in single_nb_execution
    executenb(
  File "/opt/hostedtoolcache/Python/3.12.10/x64/lib/python3.12/site-packages/nbclient/client.py", line 1319, in execute
    return NotebookClient(nb=nb, resources=resources, km=km, **kwargs).execute()
           ^^^^^^^^^^^^^^^^^^^^^^^^^^^^^^^^^^^^^^^^^^^^^^^^^^^^^^^^^^^^^^^^^^^^^
  File "/opt/hostedtoolcache/Python/3.12.10/x64/lib/python3.12/site-packages/jupyter_core/utils/__init__.py", line 158, in wrapped
    return loop.run_until_complete(inner)
           ^^^^^^^^^^^^^^^^^^^^^^^^^^^^^^
  File "/opt/hostedtoolcache/Python/3.12.10/x64/lib/python3.12/asyncio/base_events.py", line 691, in run_until_complete
    return future.result()
           ^^^^^^^^^^^^^^^
  File "/opt/hostedtoolcache/Python/3.12.10/x64/lib/python3.12/site-packages/nbclient/client.py", line 709, in async_execute
    await self.async_execute_cell(
  File "/opt/hostedtoolcache/Python/3.12.10/x64/lib/python3.12/site-packages/nbclient/client.py", line 1062, in async_execute_cell
    await self._check_raise_for_error(cell, cell_index, exec_reply)
  File "/opt/hostedtoolcache/Python/3.12.10/x64/lib/python3.12/site-packages/nbclient/client.py", line 918, in _check_raise_for_error
    raise CellExecutionError.from_cell_and_msg(cell, exec_reply_content)
nbclient.exceptions.CellExecutionError: An error occurred while executing the following cell:
------------------
Ksyms = [ -200.0, 0.0, 200 ]
for Ksym in Ksyms:
    nuda.fig.corr_setupEsymDen_fig( pname=None, constraints = constraints, Ksym = Ksym )
------------------


[31m---------------------------------------------------------------------------[39m
[31mTypeError[39m                                 Traceback (most recent call last)
[36mCell[39m[36m [39m[32mIn[7][39m[32m, line 3[39m
[32m      1[39m Ksyms = [ -[32m200.0[39m, [32m0.0[39m, [32m200[39m ]
[32m      2[39m [38;5;28;01mfor[39;00m Ksym [38;5;129;01min[39;00m Ksyms:
[32m----> [39m[32m3[39m     [43mnuda[49m[43m.[49m[43mfig[49m[43m.[49m[43mcorr_setupEsymDen_fig[49m[43m([49m[43m [49m[43mpname[49m[43m=[49m[38;5;28;43;01mNone[39;49;00m[43m,[49m[43m [49m[43mconstraints[49m[43m [49m[43m=[49m[43m [49m[43mconstraints[49m[43m,[49m[43m [49m[43mKsym[49m[43m [49m[43m=[49m[43m [49m[43mKsym[49m[43m [49m[43m)[49m

[31mTypeError[39m: corr_setupEsymDen_fig() missing 1 required positional argument: 'origine'

