Traceback (most recent call last):
  File "/opt/hostedtoolcache/Python/3.12.10/x64/lib/python3.12/site-packages/jupyter_core/utils/__init__.py", line 154, in wrapped
    asyncio.get_running_loop()
RuntimeError: no running event loop

During handling of the above exception, another exception occurred:

Traceback (most recent call last):
  File "/opt/hostedtoolcache/Python/3.12.10/x64/lib/python3.12/site-packages/jupyter_cache/executors/utils.py", line 58, in single_nb_execution
    executenb(
  File "/opt/hostedtoolcache/Python/3.12.10/x64/lib/python3.12/site-packages/nbclient/client.py", line 1319, in execute
    return NotebookClient(nb=nb, resources=resources, km=km, **kwargs).execute()
           ^^^^^^^^^^^^^^^^^^^^^^^^^^^^^^^^^^^^^^^^^^^^^^^^^^^^^^^^^^^^^^^^^^^^^
  File "/opt/hostedtoolcache/Python/3.12.10/x64/lib/python3.12/site-packages/jupyter_core/utils/__init__.py", line 158, in wrapped
    return loop.run_until_complete(inner)
           ^^^^^^^^^^^^^^^^^^^^^^^^^^^^^^
  File "/opt/hostedtoolcache/Python/3.12.10/x64/lib/python3.12/asyncio/base_events.py", line 691, in run_until_complete
    return future.result()
           ^^^^^^^^^^^^^^^
  File "/opt/hostedtoolcache/Python/3.12.10/x64/lib/python3.12/site-packages/nbclient/client.py", line 709, in async_execute
    await self.async_execute_cell(
  File "/opt/hostedtoolcache/Python/3.12.10/x64/lib/python3.12/site-packages/nbclient/client.py", line 1062, in async_execute_cell
    await self._check_raise_for_error(cell, cell_index, exec_reply)
  File "/opt/hostedtoolcache/Python/3.12.10/x64/lib/python3.12/site-packages/nbclient/client.py", line 918, in _check_raise_for_error
    raise CellExecutionError.from_cell_and_msg(cell, exec_reply_content)
nbclient.exceptions.CellExecutionError: An error occurred while executing the following cell:
------------------
den = np.linspace(0.01,0.35,10)
kfn = np.linspace(0.5,2.0,10)
mss = [ 1.0, 0.7, 0.4 ]
nuda.fig.matter_setupFFGNuc_EP_fig( pname=None, den = den, kfn = kfn, mss = mss )
------------------


[31m---------------------------------------------------------------------------[39m
[31mTypeError[39m                                 Traceback (most recent call last)
[36mCell[39m[36m [39m[32mIn[8][39m[32m, line 4[39m
[32m      2[39m kfn = np.linspace([32m0.5[39m,[32m2.0[39m,[32m10[39m)
[32m      3[39m mss = [ [32m1.0[39m, [32m0.7[39m, [32m0.4[39m ]
[32m----> [39m[32m4[39m [43mnuda[49m[43m.[49m[43mfig[49m[43m.[49m[43mmatter_setupFFGNuc_EP_fig[49m[43m([49m[43m [49m[43mpname[49m[43m=[49m[38;5;28;43;01mNone[39;49;00m[43m,[49m[43m [49m[43mden[49m[43m [49m[43m=[49m[43m [49m[43mden[49m[43m,[49m[43m [49m[43mkfn[49m[43m [49m[43m=[49m[43m [49m[43mkfn[49m[43m,[49m[43m [49m[43mmss[49m[43m [49m[43m=[49m[43m [49m[43mmss[49m[43m [49m[43m)[49m

[31mTypeError[39m: matter_setupFFGNuc_EP_fig() got an unexpected keyword argument 'kfn'

