Traceback (most recent call last):
  File "/opt/hostedtoolcache/Python/3.12.10/x64/lib/python3.12/site-packages/jupyter_core/utils/__init__.py", line 154, in wrapped
    asyncio.get_running_loop()
RuntimeError: no running event loop

During handling of the above exception, another exception occurred:

Traceback (most recent call last):
  File "/opt/hostedtoolcache/Python/3.12.10/x64/lib/python3.12/site-packages/jupyter_cache/executors/utils.py", line 58, in single_nb_execution
    executenb(
  File "/opt/hostedtoolcache/Python/3.12.10/x64/lib/python3.12/site-packages/nbclient/client.py", line 1319, in execute
    return NotebookClient(nb=nb, resources=resources, km=km, **kwargs).execute()
           ^^^^^^^^^^^^^^^^^^^^^^^^^^^^^^^^^^^^^^^^^^^^^^^^^^^^^^^^^^^^^^^^^^^^^
  File "/opt/hostedtoolcache/Python/3.12.10/x64/lib/python3.12/site-packages/jupyter_core/utils/__init__.py", line 158, in wrapped
    return loop.run_until_complete(inner)
           ^^^^^^^^^^^^^^^^^^^^^^^^^^^^^^
  File "/opt/hostedtoolcache/Python/3.12.10/x64/lib/python3.12/asyncio/base_events.py", line 691, in run_until_complete
    return future.result()
           ^^^^^^^^^^^^^^^
  File "/opt/hostedtoolcache/Python/3.12.10/x64/lib/python3.12/site-packages/nbclient/client.py", line 709, in async_execute
    await self.async_execute_cell(
  File "/opt/hostedtoolcache/Python/3.12.10/x64/lib/python3.12/site-packages/nbclient/client.py", line 1062, in async_execute_cell
    await self._check_raise_for_error(cell, cell_index, exec_reply)
  File "/opt/hostedtoolcache/Python/3.12.10/x64/lib/python3.12/site-packages/nbclient/client.py", line 918, in _check_raise_for_error
    raise CellExecutionError.from_cell_and_msg(cell, exec_reply_content)
nbclient.exceptions.CellExecutionError: An error occurred while executing the following cell:
------------------
for model in models:
    crust = nuda.crust.setupCrust( model = model )
    #crust.print_outputs( )
------------------


[31m---------------------------------------------------------------------------[39m
[31mAttributeError[39m                            Traceback (most recent call last)
[36mCell[39m[36m [39m[32mIn[4][39m[32m, line 2[39m
[32m      1[39m [38;5;28;01mfor[39;00m model [38;5;129;01min[39;00m models:
[32m----> [39m[32m2[39m     crust = [43mnuda[49m[43m.[49m[43mcrust[49m[43m.[49m[43msetupCrust[49m[43m([49m[43m [49m[43mmodel[49m[43m [49m[43m=[49m[43m [49m[43mmodel[49m[43m [49m[43m)[49m
[32m      3[39m     [38;5;66;03m#crust.print_outputs( )[39;00m

[36mFile [39m[32m~/work/nucleardatapy/nucleardatapy/version-0.2/nucleardatapy/crust/setup_crust.py:179[39m, in [36msetupCrust.__init__[39m[34m(self, model)[39m
[32m    177[39m [38;5;66;03m# NEP[39;00m
[32m    178[39m nep = nuda.matter.setupNEP( model = [33m'[39m[33mESkyrme[39m[33m'[39m, param = [33m'[39m[33mBSk22[39m[33m'[39m )
[32m--> [39m[32m179[39m [38;5;28mself[39m.nsat = [43mnep[49m[43m.[49m[43msat[49m
[32m    180[39m [38;5;28mself[39m.Esym = nep.Esym
[32m    181[39m [38;5;28mself[39m.Lsym = nep.Lsym

[31mAttributeError[39m: 'setupNEP' object has no attribute 'sat'

